ERROR 2018-09-14 03:08:46,765 exception 135 Internal Server Error: /GetInfoView/1/
Traceback (most recent call last):
  File "/Applications/anaconda3/lib/python3.6/site-packages/django/core/handlers/exception.py", line 41, in inner
    response = get_response(request)
  File "/Applications/anaconda3/lib/python3.6/site-packages/django/core/handlers/base.py", line 187, in _get_response
    response = self.process_exception_by_middleware(e, request)
  File "/Applications/anaconda3/lib/python3.6/site-packages/django/core/handlers/base.py", line 185, in _get_response
    response = wrapped_callback(request, *callback_args, **callback_kwargs)
  File "/Applications/anaconda3/lib/python3.6/site-packages/django/views/generic/base.py", line 68, in view
    return self.dispatch(request, *args, **kwargs)
  File "/Applications/anaconda3/lib/python3.6/site-packages/django/views/generic/base.py", line 88, in dispatch
    return handler(request, *args, **kwargs)
  File "/Users/mq/Desktop/work_Pro/Code/Project/WeChat/Tax_consult/wechat/views.py", line 147, in get
    return HttpResponse("p1 = {a}".format(param1))
KeyError: 'a'
ERROR 2018-09-14 03:08:46,806 basehttp 124 "GET /GetInfoView/1/ HTTP/1.1" 500 27
ERROR 2018-09-14 03:08:47,804 exception 135 Internal Server Error: /GetInfoView/1/
Traceback (most recent call last):
  File "/Applications/anaconda3/lib/python3.6/site-packages/django/core/handlers/exception.py", line 41, in inner
    response = get_response(request)
  File "/Applications/anaconda3/lib/python3.6/site-packages/django/core/handlers/base.py", line 187, in _get_response
    response = self.process_exception_by_middleware(e, request)
  File "/Applications/anaconda3/lib/python3.6/site-packages/django/core/handlers/base.py", line 185, in _get_response
    response = wrapped_callback(request, *callback_args, **callback_kwargs)
  File "/Applications/anaconda3/lib/python3.6/site-packages/django/views/generic/base.py", line 68, in view
    return self.dispatch(request, *args, **kwargs)
  File "/Applications/anaconda3/lib/python3.6/site-packages/django/views/generic/base.py", line 88, in dispatch
    return handler(request, *args, **kwargs)
  File "/Users/mq/Desktop/work_Pro/Code/Project/WeChat/Tax_consult/wechat/views.py", line 147, in get
    return HttpResponse("p1 = {a}".format(param1))
KeyError: 'a'
ERROR 2018-09-14 03:08:47,805 basehttp 124 "GET /GetInfoView/1/ HTTP/1.1" 500 27
ERROR 2018-09-14 03:08:49,357 exception 135 Internal Server Error: /GetInfoView/1/
Traceback (most recent call last):
  File "/Applications/anaconda3/lib/python3.6/site-packages/django/core/handlers/exception.py", line 41, in inner
    response = get_response(request)
  File "/Applications/anaconda3/lib/python3.6/site-packages/django/core/handlers/base.py", line 187, in _get_response
    response = self.process_exception_by_middleware(e, request)
  File "/Applications/anaconda3/lib/python3.6/site-packages/django/core/handlers/base.py", line 185, in _get_response
    response = wrapped_callback(request, *callback_args, **callback_kwargs)
  File "/Applications/anaconda3/lib/python3.6/site-packages/django/views/generic/base.py", line 68, in view
    return self.dispatch(request, *args, **kwargs)
  File "/Applications/anaconda3/lib/python3.6/site-packages/django/views/generic/base.py", line 88, in dispatch
    return handler(request, *args, **kwargs)
  File "/Users/mq/Desktop/work_Pro/Code/Project/WeChat/Tax_consult/wechat/views.py", line 147, in get
    return HttpResponse("p1 = {a}".format(param1))
KeyError: 'a'
ERROR 2018-09-14 03:08:49,360 basehttp 124 "GET /GetInfoView/1/ HTTP/1.1" 500 27
ERROR 2018-09-14 03:24:08,496 exception 135 Internal Server Error: /GetInfoView/3952/
Traceback (most recent call last):
  File "/Applications/anaconda3/lib/python3.6/site-packages/django/core/handlers/exception.py", line 41, in inner
    response = get_response(request)
  File "/Applications/anaconda3/lib/python3.6/site-packages/django/core/handlers/base.py", line 187, in _get_response
    response = self.process_exception_by_middleware(e, request)
  File "/Applications/anaconda3/lib/python3.6/site-packages/django/core/handlers/base.py", line 185, in _get_response
    response = wrapped_callback(request, *callback_args, **callback_kwargs)
  File "/Applications/anaconda3/lib/python3.6/site-packages/django/views/generic/base.py", line 68, in view
    return self.dispatch(request, *args, **kwargs)
  File "/Applications/anaconda3/lib/python3.6/site-packages/django/views/generic/base.py", line 88, in dispatch
    return handler(request, *args, **kwargs)
  File "/Users/mq/Desktop/work_Pro/Code/Project/WeChat/Tax_consult/wechat/views.py", line 150, in get
    answer = answer[0]
IndexError: index 0 is out of bounds for axis 0 with size 0
ERROR 2018-09-14 03:24:08,508 basehttp 124 "GET /GetInfoView/3952/ HTTP/1.1" 500 27
ERROR 2018-09-14 03:24:23,522 exception 135 Internal Server Error: /GetInfoView/3952/
Traceback (most recent call last):
  File "/Applications/anaconda3/lib/python3.6/site-packages/django/core/handlers/exception.py", line 41, in inner
    response = get_response(request)
  File "/Applications/anaconda3/lib/python3.6/site-packages/django/core/handlers/base.py", line 187, in _get_response
    response = self.process_exception_by_middleware(e, request)
  File "/Applications/anaconda3/lib/python3.6/site-packages/django/core/handlers/base.py", line 185, in _get_response
    response = wrapped_callback(request, *callback_args, **callback_kwargs)
  File "/Applications/anaconda3/lib/python3.6/site-packages/django/views/generic/base.py", line 68, in view
    return self.dispatch(request, *args, **kwargs)
  File "/Applications/anaconda3/lib/python3.6/site-packages/django/views/generic/base.py", line 88, in dispatch
    return handler(request, *args, **kwargs)
  File "/Users/mq/Desktop/work_Pro/Code/Project/WeChat/Tax_consult/wechat/views.py", line 150, in get
    answer = answer[0]
IndexError: index 0 is out of bounds for axis 0 with size 0
ERROR 2018-09-14 03:24:23,523 basehttp 124 "GET /GetInfoView/3952/ HTTP/1.1" 500 27
ERROR 2018-09-14 03:24:50,453 exception 135 Internal Server Error: /GetInfoView/3952/
Traceback (most recent call last):
  File "/Applications/anaconda3/lib/python3.6/site-packages/django/core/handlers/exception.py", line 41, in inner
    response = get_response(request)
  File "/Applications/anaconda3/lib/python3.6/site-packages/django/core/handlers/base.py", line 187, in _get_response
    response = self.process_exception_by_middleware(e, request)
  File "/Applications/anaconda3/lib/python3.6/site-packages/django/core/handlers/base.py", line 185, in _get_response
    response = wrapped_callback(request, *callback_args, **callback_kwargs)
  File "/Applications/anaconda3/lib/python3.6/site-packages/django/views/generic/base.py", line 68, in view
    return self.dispatch(request, *args, **kwargs)
  File "/Applications/anaconda3/lib/python3.6/site-packages/django/views/generic/base.py", line 88, in dispatch
    return handler(request, *args, **kwargs)
  File "/Users/mq/Desktop/work_Pro/Code/Project/WeChat/Tax_consult/wechat/views.py", line 150, in get
    answer = answer[0]
IndexError: index 0 is out of bounds for axis 0 with size 0
ERROR 2018-09-14 03:24:50,460 basehttp 124 "GET /GetInfoView/3952/ HTTP/1.1" 500 27
ERROR 2018-09-14 03:24:57,638 exception 135 Internal Server Error: /GetInfoView/3952/
Traceback (most recent call last):
  File "/Applications/anaconda3/lib/python3.6/site-packages/django/core/handlers/exception.py", line 41, in inner
    response = get_response(request)
  File "/Applications/anaconda3/lib/python3.6/site-packages/django/core/handlers/base.py", line 187, in _get_response
    response = self.process_exception_by_middleware(e, request)
  File "/Applications/anaconda3/lib/python3.6/site-packages/django/core/handlers/base.py", line 185, in _get_response
    response = wrapped_callback(request, *callback_args, **callback_kwargs)
  File "/Applications/anaconda3/lib/python3.6/site-packages/django/views/generic/base.py", line 68, in view
    return self.dispatch(request, *args, **kwargs)
  File "/Applications/anaconda3/lib/python3.6/site-packages/django/views/generic/base.py", line 88, in dispatch
    return handler(request, *args, **kwargs)
  File "/Users/mq/Desktop/work_Pro/Code/Project/WeChat/Tax_consult/wechat/views.py", line 150, in get
    answer = answer[0]
IndexError: index 0 is out of bounds for axis 0 with size 0
ERROR 2018-09-14 03:24:57,640 basehttp 124 "GET /GetInfoView/3952/ HTTP/1.1" 500 27
ERROR 2018-09-14 03:25:12,993 exception 135 Internal Server Error: /GetInfoView/3952/
Traceback (most recent call last):
  File "/Applications/anaconda3/lib/python3.6/site-packages/django/core/handlers/exception.py", line 41, in inner
    response = get_response(request)
  File "/Applications/anaconda3/lib/python3.6/site-packages/django/core/handlers/base.py", line 187, in _get_response
    response = self.process_exception_by_middleware(e, request)
  File "/Applications/anaconda3/lib/python3.6/site-packages/django/core/handlers/base.py", line 185, in _get_response
    response = wrapped_callback(request, *callback_args, **callback_kwargs)
  File "/Applications/anaconda3/lib/python3.6/site-packages/django/views/generic/base.py", line 68, in view
    return self.dispatch(request, *args, **kwargs)
  File "/Applications/anaconda3/lib/python3.6/site-packages/django/views/generic/base.py", line 88, in dispatch
    return handler(request, *args, **kwargs)
  File "/Users/mq/Desktop/work_Pro/Code/Project/WeChat/Tax_consult/wechat/views.py", line 150, in get
    answer = answer[0]
IndexError: index 0 is out of bounds for axis 0 with size 0
ERROR 2018-09-14 03:25:13,001 basehttp 124 "GET /GetInfoView/3952/ HTTP/1.1" 500 27
ERROR 2018-09-14 03:27:33,542 exception 135 Internal Server Error: /GetInfoView/3952/
Traceback (most recent call last):
  File "/Applications/anaconda3/lib/python3.6/site-packages/django/core/handlers/exception.py", line 41, in inner
    response = get_response(request)
  File "/Applications/anaconda3/lib/python3.6/site-packages/django/core/handlers/base.py", line 187, in _get_response
    response = self.process_exception_by_middleware(e, request)
  File "/Applications/anaconda3/lib/python3.6/site-packages/django/core/handlers/base.py", line 185, in _get_response
    response = wrapped_callback(request, *callback_args, **callback_kwargs)
  File "/Applications/anaconda3/lib/python3.6/site-packages/django/views/generic/base.py", line 68, in view
    return self.dispatch(request, *args, **kwargs)
  File "/Applications/anaconda3/lib/python3.6/site-packages/django/views/generic/base.py", line 88, in dispatch
    return handler(request, *args, **kwargs)
  File "/Users/mq/Desktop/work_Pro/Code/Project/WeChat/Tax_consult/wechat/views.py", line 150, in get
    answer = answer[0]
IndexError: index 0 is out of bounds for axis 0 with size 0
ERROR 2018-09-14 03:27:33,549 basehttp 124 "GET /GetInfoView/3952/ HTTP/1.1" 500 27
ERROR 2018-09-14 03:27:34,429 exception 135 Internal Server Error: /GetInfoView/3952/
Traceback (most recent call last):
  File "/Applications/anaconda3/lib/python3.6/site-packages/django/core/handlers/exception.py", line 41, in inner
    response = get_response(request)
  File "/Applications/anaconda3/lib/python3.6/site-packages/django/core/handlers/base.py", line 187, in _get_response
    response = self.process_exception_by_middleware(e, request)
  File "/Applications/anaconda3/lib/python3.6/site-packages/django/core/handlers/base.py", line 185, in _get_response
    response = wrapped_callback(request, *callback_args, **callback_kwargs)
  File "/Applications/anaconda3/lib/python3.6/site-packages/django/views/generic/base.py", line 68, in view
    return self.dispatch(request, *args, **kwargs)
  File "/Applications/anaconda3/lib/python3.6/site-packages/django/views/generic/base.py", line 88, in dispatch
    return handler(request, *args, **kwargs)
  File "/Users/mq/Desktop/work_Pro/Code/Project/WeChat/Tax_consult/wechat/views.py", line 150, in get
    answer = answer[0]
IndexError: index 0 is out of bounds for axis 0 with size 0
ERROR 2018-09-14 03:27:34,431 basehttp 124 "GET /GetInfoView/3952/ HTTP/1.1" 500 27
ERROR 2018-09-14 03:35:30,744 exception 135 Internal Server Error: /GetInfoView/3952/
Traceback (most recent call last):
  File "/Applications/anaconda3/lib/python3.6/site-packages/django/core/handlers/exception.py", line 41, in inner
    response = get_response(request)
  File "/Applications/anaconda3/lib/python3.6/site-packages/django/core/handlers/base.py", line 187, in _get_response
    response = self.process_exception_by_middleware(e, request)
  File "/Applications/anaconda3/lib/python3.6/site-packages/django/core/handlers/base.py", line 185, in _get_response
    response = wrapped_callback(request, *callback_args, **callback_kwargs)
  File "/Applications/anaconda3/lib/python3.6/site-packages/django/views/generic/base.py", line 68, in view
    return self.dispatch(request, *args, **kwargs)
  File "/Applications/anaconda3/lib/python3.6/site-packages/django/views/generic/base.py", line 88, in dispatch
    return handler(request, *args, **kwargs)
  File "/Users/mq/Desktop/work_Pro/Code/Project/WeChat/Tax_consult/wechat/views.py", line 148, in get
    answer = answer[0]
IndexError: index 0 is out of bounds for axis 0 with size 0
ERROR 2018-09-14 03:35:30,753 basehttp 124 "GET /GetInfoView/3952/ HTTP/1.1" 500 27
ERROR 2018-09-14 03:35:40,134 exception 135 Internal Server Error: /GetInfoView/3952/
Traceback (most recent call last):
  File "/Applications/anaconda3/lib/python3.6/site-packages/django/core/handlers/exception.py", line 41, in inner
    response = get_response(request)
  File "/Applications/anaconda3/lib/python3.6/site-packages/django/core/handlers/base.py", line 187, in _get_response
    response = self.process_exception_by_middleware(e, request)
  File "/Applications/anaconda3/lib/python3.6/site-packages/django/core/handlers/base.py", line 185, in _get_response
    response = wrapped_callback(request, *callback_args, **callback_kwargs)
  File "/Applications/anaconda3/lib/python3.6/site-packages/django/views/generic/base.py", line 68, in view
    return self.dispatch(request, *args, **kwargs)
  File "/Applications/anaconda3/lib/python3.6/site-packages/django/views/generic/base.py", line 88, in dispatch
    return handler(request, *args, **kwargs)
  File "/Users/mq/Desktop/work_Pro/Code/Project/WeChat/Tax_consult/wechat/views.py", line 148, in get
    answer = answer[0]
IndexError: index 0 is out of bounds for axis 0 with size 0
ERROR 2018-09-14 03:35:40,142 basehttp 124 "GET /GetInfoView/3952/ HTTP/1.1" 500 27
ERROR 2018-09-14 06:11:43,522 exception 135 Internal Server Error: /GetInfoView/123/
Traceback (most recent call last):
  File "/Applications/anaconda3/lib/python3.6/site-packages/django/core/handlers/exception.py", line 41, in inner
    response = get_response(request)
  File "/Applications/anaconda3/lib/python3.6/site-packages/django/core/handlers/base.py", line 187, in _get_response
    response = self.process_exception_by_middleware(e, request)
  File "/Applications/anaconda3/lib/python3.6/site-packages/django/core/handlers/base.py", line 185, in _get_response
    response = wrapped_callback(request, *callback_args, **callback_kwargs)
  File "/Applications/anaconda3/lib/python3.6/site-packages/django/views/generic/base.py", line 68, in view
    return self.dispatch(request, *args, **kwargs)
  File "/Applications/anaconda3/lib/python3.6/site-packages/django/views/generic/base.py", line 88, in dispatch
    return handler(request, *args, **kwargs)
  File "/Users/mq/Desktop/work_Pro/Code/Project/WeChat/Tax_consult/wechat/views.py", line 144, in get
    answer = answer[0]
IndexError: index 0 is out of bounds for axis 0 with size 0
ERROR 2018-09-14 06:11:43,526 basehttp 124 "GET /GetInfoView/123/ HTTP/1.1" 500 27
ERROR 2018-09-14 06:12:57,249 exception 135 Internal Server Error: /GetInfoView/123/
Traceback (most recent call last):
  File "/Applications/anaconda3/lib/python3.6/site-packages/django/core/handlers/exception.py", line 41, in inner
    response = get_response(request)
  File "/Applications/anaconda3/lib/python3.6/site-packages/django/core/handlers/base.py", line 187, in _get_response
    response = self.process_exception_by_middleware(e, request)
  File "/Applications/anaconda3/lib/python3.6/site-packages/django/core/handlers/base.py", line 185, in _get_response
    response = wrapped_callback(request, *callback_args, **callback_kwargs)
  File "/Applications/anaconda3/lib/python3.6/site-packages/django/views/generic/base.py", line 68, in view
    return self.dispatch(request, *args, **kwargs)
  File "/Applications/anaconda3/lib/python3.6/site-packages/django/views/generic/base.py", line 88, in dispatch
    return handler(request, *args, **kwargs)
  File "/Users/mq/Desktop/work_Pro/Code/Project/WeChat/Tax_consult/wechat/views.py", line 144, in get
    answer = answer[0]
IndexError: index 0 is out of bounds for axis 0 with size 0
ERROR 2018-09-14 06:12:57,256 basehttp 124 "GET /GetInfoView/123/ HTTP/1.1" 500 27
ERROR 2018-09-14 06:13:25,505 exception 135 Internal Server Error: /GetInfoView/123/
Traceback (most recent call last):
  File "/Applications/anaconda3/lib/python3.6/site-packages/django/core/handlers/exception.py", line 41, in inner
    response = get_response(request)
  File "/Applications/anaconda3/lib/python3.6/site-packages/django/core/handlers/base.py", line 187, in _get_response
    response = self.process_exception_by_middleware(e, request)
  File "/Applications/anaconda3/lib/python3.6/site-packages/django/core/handlers/base.py", line 185, in _get_response
    response = wrapped_callback(request, *callback_args, **callback_kwargs)
  File "/Applications/anaconda3/lib/python3.6/site-packages/django/views/generic/base.py", line 68, in view
    return self.dispatch(request, *args, **kwargs)
  File "/Applications/anaconda3/lib/python3.6/site-packages/django/views/generic/base.py", line 88, in dispatch
    return handler(request, *args, **kwargs)
  File "/Users/mq/Desktop/work_Pro/Code/Project/WeChat/Tax_consult/wechat/views.py", line 149, in get
    return render(request, content=content)
TypeError: render() got an unexpected keyword argument 'content'
ERROR 2018-09-14 06:13:25,573 basehttp 124 "GET /GetInfoView/123/ HTTP/1.1" 500 27
ERROR 2018-09-14 06:13:28,210 exception 135 Internal Server Error: /GetInfoView/123/
Traceback (most recent call last):
  File "/Applications/anaconda3/lib/python3.6/site-packages/django/core/handlers/exception.py", line 41, in inner
    response = get_response(request)
  File "/Applications/anaconda3/lib/python3.6/site-packages/django/core/handlers/base.py", line 187, in _get_response
    response = self.process_exception_by_middleware(e, request)
  File "/Applications/anaconda3/lib/python3.6/site-packages/django/core/handlers/base.py", line 185, in _get_response
    response = wrapped_callback(request, *callback_args, **callback_kwargs)
  File "/Applications/anaconda3/lib/python3.6/site-packages/django/views/generic/base.py", line 68, in view
    return self.dispatch(request, *args, **kwargs)
  File "/Applications/anaconda3/lib/python3.6/site-packages/django/views/generic/base.py", line 88, in dispatch
    return handler(request, *args, **kwargs)
  File "/Users/mq/Desktop/work_Pro/Code/Project/WeChat/Tax_consult/wechat/views.py", line 149, in get
    return render(request, content=content)
TypeError: render() got an unexpected keyword argument 'content'
ERROR 2018-09-14 06:13:28,211 basehttp 124 "GET /GetInfoView/123/ HTTP/1.1" 500 27
ERROR 2018-09-14 06:20:42,841 exception 135 Internal Server Error: /GetInfoView/123/
Traceback (most recent call last):
  File "/Applications/anaconda3/lib/python3.6/site-packages/django/core/handlers/exception.py", line 41, in inner
    response = get_response(request)
  File "/Applications/anaconda3/lib/python3.6/site-packages/django/core/handlers/base.py", line 187, in _get_response
    response = self.process_exception_by_middleware(e, request)
  File "/Applications/anaconda3/lib/python3.6/site-packages/django/core/handlers/base.py", line 185, in _get_response
    response = wrapped_callback(request, *callback_args, **callback_kwargs)
  File "/Applications/anaconda3/lib/python3.6/site-packages/django/views/generic/base.py", line 68, in view
    return self.dispatch(request, *args, **kwargs)
  File "/Applications/anaconda3/lib/python3.6/site-packages/django/views/generic/base.py", line 88, in dispatch
    return handler(request, *args, **kwargs)
  File "/Users/mq/Desktop/work_Pro/Code/Project/WeChat/Tax_consult/wechat/views.py", line 149, in get
    return render(request, content=content)
TypeError: render() got an unexpected keyword argument 'content'
ERROR 2018-09-14 06:20:42,977 basehttp 124 "GET /GetInfoView/123/ HTTP/1.1" 500 27
ERROR 2018-09-14 06:21:13,074 exception 135 Internal Server Error: /GetInfoView/123/
Traceback (most recent call last):
  File "/Applications/anaconda3/lib/python3.6/site-packages/django/core/handlers/exception.py", line 41, in inner
    response = get_response(request)
  File "/Applications/anaconda3/lib/python3.6/site-packages/django/core/handlers/base.py", line 187, in _get_response
    response = self.process_exception_by_middleware(e, request)
  File "/Applications/anaconda3/lib/python3.6/site-packages/django/core/handlers/base.py", line 185, in _get_response
    response = wrapped_callback(request, *callback_args, **callback_kwargs)
  File "/Applications/anaconda3/lib/python3.6/site-packages/django/views/generic/base.py", line 68, in view
    return self.dispatch(request, *args, **kwargs)
  File "/Applications/anaconda3/lib/python3.6/site-packages/django/views/generic/base.py", line 88, in dispatch
    return handler(request, *args, **kwargs)
  File "/Users/mq/Desktop/work_Pro/Code/Project/WeChat/Tax_consult/wechat/views.py", line 149, in get
    return render(request, content=content)
TypeError: render() got an unexpected keyword argument 'content'
ERROR 2018-09-14 06:21:13,111 basehttp 124 "GET /GetInfoView/123/ HTTP/1.1" 500 27
ERROR 2018-09-14 07:02:51,939 exception 135 Internal Server Error: /GetListView/增值税/
Traceback (most recent call last):
  File "/Applications/anaconda3/lib/python3.6/site-packages/django/core/handlers/exception.py", line 41, in inner
    response = get_response(request)
  File "/Applications/anaconda3/lib/python3.6/site-packages/django/core/handlers/base.py", line 187, in _get_response
    response = self.process_exception_by_middleware(e, request)
  File "/Applications/anaconda3/lib/python3.6/site-packages/django/core/handlers/base.py", line 185, in _get_response
    response = wrapped_callback(request, *callback_args, **callback_kwargs)
  File "/Applications/anaconda3/lib/python3.6/site-packages/django/views/generic/base.py", line 68, in view
    return self.dispatch(request, *args, **kwargs)
  File "/Applications/anaconda3/lib/python3.6/site-packages/django/views/generic/base.py", line 88, in dispatch
    return handler(request, *args, **kwargs)
  File "/Users/mq/Desktop/work_Pro/Code/Project/WeChat/Tax_consult/wechat/views.py", line 165, in get
    sql = "select * from 'asks_answer' where class4 LIKE '%{ask}%'".format(ask=ask_message)
NameError: name 'ask_message' is not defined
ERROR 2018-09-14 07:02:51,973 basehttp 124 "GET /GetListView/%E5%A2%9E%E5%80%BC%E7%A8%8E/ HTTP/1.1" 500 27
ERROR 2018-09-14 07:11:12,818 exception 135 Internal Server Error: /GetInfoView/123/
Traceback (most recent call last):
  File "/Applications/anaconda3/lib/python3.6/site-packages/django/core/handlers/exception.py", line 41, in inner
    response = get_response(request)
  File "/Applications/anaconda3/lib/python3.6/site-packages/django/core/handlers/base.py", line 187, in _get_response
    response = self.process_exception_by_middleware(e, request)
  File "/Applications/anaconda3/lib/python3.6/site-packages/django/core/handlers/base.py", line 185, in _get_response
    response = wrapped_callback(request, *callback_args, **callback_kwargs)
  File "/Applications/anaconda3/lib/python3.6/site-packages/django/views/generic/base.py", line 68, in view
    return self.dispatch(request, *args, **kwargs)
  File "/Applications/anaconda3/lib/python3.6/site-packages/django/views/generic/base.py", line 88, in dispatch
    return handler(request, *args, **kwargs)
  File "/Users/mq/Desktop/work_Pro/Code/Project/WeChat/Tax_consult/wechat/views.py", line 150, in get
    answer = answer[0]
IndexError: index 0 is out of bounds for axis 0 with size 0
ERROR 2018-09-14 07:11:12,871 basehttp 124 "GET /GetInfoView/123/ HTTP/1.1" 500 27
ERROR 2018-09-14 07:11:19,487 exception 135 Internal Server Error: /GetInfoView/1234/
Traceback (most recent call last):
  File "/Applications/anaconda3/lib/python3.6/site-packages/django/core/handlers/exception.py", line 41, in inner
    response = get_response(request)
  File "/Applications/anaconda3/lib/python3.6/site-packages/django/core/handlers/base.py", line 187, in _get_response
    response = self.process_exception_by_middleware(e, request)
  File "/Applications/anaconda3/lib/python3.6/site-packages/django/core/handlers/base.py", line 185, in _get_response
    response = wrapped_callback(request, *callback_args, **callback_kwargs)
  File "/Applications/anaconda3/lib/python3.6/site-packages/django/views/generic/base.py", line 68, in view
    return self.dispatch(request, *args, **kwargs)
  File "/Applications/anaconda3/lib/python3.6/site-packages/django/views/generic/base.py", line 88, in dispatch
    return handler(request, *args, **kwargs)
  File "/Users/mq/Desktop/work_Pro/Code/Project/WeChat/Tax_consult/wechat/views.py", line 150, in get
    answer = answer[0]
IndexError: index 0 is out of bounds for axis 0 with size 0
ERROR 2018-09-14 07:11:19,493 basehttp 124 "GET /GetInfoView/1234/ HTTP/1.1" 500 27
ERROR 2018-09-17 03:12:33,985 exception 135 Internal Server Error: /GetListView/
Traceback (most recent call last):
  File "/Applications/anaconda3/lib/python3.6/site-packages/django/core/handlers/exception.py", line 41, in inner
    response = get_response(request)
  File "/Applications/anaconda3/lib/python3.6/site-packages/django/core/handlers/base.py", line 187, in _get_response
    response = self.process_exception_by_middleware(e, request)
  File "/Applications/anaconda3/lib/python3.6/site-packages/django/core/handlers/base.py", line 185, in _get_response
    response = wrapped_callback(request, *callback_args, **callback_kwargs)
  File "/Applications/anaconda3/lib/python3.6/site-packages/django/views/generic/base.py", line 68, in view
    return self.dispatch(request, *args, **kwargs)
  File "/Applications/anaconda3/lib/python3.6/site-packages/django/views/generic/base.py", line 88, in dispatch
    return handler(request, *args, **kwargs)
TypeError: get() missing 1 required positional argument: 'param'
ERROR 2018-09-17 03:12:34,024 basehttp 124 "GET /GetListView/ HTTP/1.1" 500 27
ERROR 2018-09-17 03:12:35,388 exception 135 Internal Server Error: /GetListView/
Traceback (most recent call last):
  File "/Applications/anaconda3/lib/python3.6/site-packages/django/core/handlers/exception.py", line 41, in inner
    response = get_response(request)
  File "/Applications/anaconda3/lib/python3.6/site-packages/django/core/handlers/base.py", line 187, in _get_response
    response = self.process_exception_by_middleware(e, request)
  File "/Applications/anaconda3/lib/python3.6/site-packages/django/core/handlers/base.py", line 185, in _get_response
    response = wrapped_callback(request, *callback_args, **callback_kwargs)
  File "/Applications/anaconda3/lib/python3.6/site-packages/django/views/generic/base.py", line 68, in view
    return self.dispatch(request, *args, **kwargs)
  File "/Applications/anaconda3/lib/python3.6/site-packages/django/views/generic/base.py", line 88, in dispatch
    return handler(request, *args, **kwargs)
TypeError: get() missing 1 required positional argument: 'param'
ERROR 2018-09-17 03:12:35,389 basehttp 124 "GET /GetListView/ HTTP/1.1" 500 27
ERROR 2018-09-17 03:12:50,496 exception 135 Internal Server Error: /GetListView/
Traceback (most recent call last):
  File "/Applications/anaconda3/lib/python3.6/site-packages/django/core/handlers/exception.py", line 41, in inner
    response = get_response(request)
  File "/Applications/anaconda3/lib/python3.6/site-packages/django/core/handlers/base.py", line 187, in _get_response
    response = self.process_exception_by_middleware(e, request)
  File "/Applications/anaconda3/lib/python3.6/site-packages/django/core/handlers/base.py", line 185, in _get_response
    response = wrapped_callback(request, *callback_args, **callback_kwargs)
  File "/Applications/anaconda3/lib/python3.6/site-packages/django/views/generic/base.py", line 68, in view
    return self.dispatch(request, *args, **kwargs)
  File "/Applications/anaconda3/lib/python3.6/site-packages/django/views/generic/base.py", line 88, in dispatch
    return handler(request, *args, **kwargs)
TypeError: get() missing 1 required positional argument: 'param'
ERROR 2018-09-17 03:12:50,536 basehttp 124 "GET /GetListView/ HTTP/1.1" 500 27
ERROR 2018-09-17 07:50:53,218 basehttp 124 "POST /talk/ HTTP/1.1" 500 59
ERROR 2018-09-17 08:42:02,474 exception 135 Internal Server Error: /talk/
Traceback (most recent call last):
  File "/Applications/anaconda3/lib/python3.6/site-packages/django/db/backends/utils.py", line 62, in execute
    return self.cursor.execute(sql)
  File "/Applications/anaconda3/lib/python3.6/site-packages/django/db/backends/sqlite3/base.py", line 326, in execute
    return Database.Cursor.execute(self, query)
sqlite3.OperationalError: unrecognized token: "#"

The above exception was the direct cause of the following exception:

Traceback (most recent call last):
  File "/Applications/anaconda3/lib/python3.6/site-packages/pandas/io/sql.py", line 1409, in execute
    cur.execute(*args)
  File "/Applications/anaconda3/lib/python3.6/site-packages/django/db/backends/utils.py", line 64, in execute
    return self.cursor.execute(sql, params)
  File "/Applications/anaconda3/lib/python3.6/site-packages/django/db/utils.py", line 94, in __exit__
    six.reraise(dj_exc_type, dj_exc_value, traceback)
  File "/Applications/anaconda3/lib/python3.6/site-packages/django/utils/six.py", line 685, in reraise
    raise value.with_traceback(tb)
  File "/Applications/anaconda3/lib/python3.6/site-packages/django/db/backends/utils.py", line 62, in execute
    return self.cursor.execute(sql)
  File "/Applications/anaconda3/lib/python3.6/site-packages/django/db/backends/sqlite3/base.py", line 326, in execute
    return Database.Cursor.execute(self, query)
django.db.utils.OperationalError: unrecognized token: "#"

During handling of the above exception, another exception occurred:

Traceback (most recent call last):
  File "/Applications/anaconda3/lib/python3.6/site-packages/django/core/handlers/exception.py", line 41, in inner
    response = get_response(request)
  File "/Applications/anaconda3/lib/python3.6/site-packages/django/core/handlers/base.py", line 187, in _get_response
    response = self.process_exception_by_middleware(e, request)
  File "/Applications/anaconda3/lib/python3.6/site-packages/django/core/handlers/base.py", line 185, in _get_response
    response = wrapped_callback(request, *callback_args, **callback_kwargs)
  File "/Applications/anaconda3/lib/python3.6/site-packages/django/views/decorators/csrf.py", line 58, in wrapped_view
    return view_func(*args, **kwargs)
  File "/Applications/anaconda3/lib/python3.6/site-packages/django/views/generic/base.py", line 68, in view
    return self.dispatch(request, *args, **kwargs)
  File "/Applications/anaconda3/lib/python3.6/site-packages/django/views/generic/base.py", line 88, in dispatch
    return handler(request, *args, **kwargs)
  File "/Users/mq/Desktop/work_Pro/Code/Project/WeChat/Tax_consult/wechat/views.py", line 217, in post
    list_res = self.data_query(list_dic[1])
  File "/Users/mq/Desktop/work_Pro/Code/Project/WeChat/Tax_consult/wechat/views.py", line 257, in data_query
    df = pd.read_sql_query(sql, connection)
  File "/Applications/anaconda3/lib/python3.6/site-packages/pandas/io/sql.py", line 332, in read_sql_query
    parse_dates=parse_dates, chunksize=chunksize)
  File "/Applications/anaconda3/lib/python3.6/site-packages/pandas/io/sql.py", line 1444, in read_query
    cursor = self.execute(*args)
  File "/Applications/anaconda3/lib/python3.6/site-packages/pandas/io/sql.py", line 1421, in execute
    raise_with_traceback(ex)
  File "/Applications/anaconda3/lib/python3.6/site-packages/pandas/compat/__init__.py", line 385, in raise_with_traceback
    raise exc.with_traceback(traceback)
  File "/Applications/anaconda3/lib/python3.6/site-packages/pandas/io/sql.py", line 1409, in execute
    cur.execute(*args)
  File "/Applications/anaconda3/lib/python3.6/site-packages/django/db/backends/utils.py", line 64, in execute
    return self.cursor.execute(sql, params)
  File "/Applications/anaconda3/lib/python3.6/site-packages/django/db/utils.py", line 94, in __exit__
    six.reraise(dj_exc_type, dj_exc_value, traceback)
  File "/Applications/anaconda3/lib/python3.6/site-packages/django/utils/six.py", line 685, in reraise
    raise value.with_traceback(tb)
  File "/Applications/anaconda3/lib/python3.6/site-packages/django/db/backends/utils.py", line 62, in execute
    return self.cursor.execute(sql)
  File "/Applications/anaconda3/lib/python3.6/site-packages/django/db/backends/sqlite3/base.py", line 326, in execute
    return Database.Cursor.execute(self, query)
pandas.io.sql.DatabaseError: Execution failed on sql 'select * from 'asks_answer' where class4='<a href='#' onclick=showAsk('贷款卡年审需要些什么资料?')>贷款卡年审需要些什么资料?</a>'': unrecognized token: "#"
ERROR 2018-09-17 08:42:02,483 basehttp 124 "POST /talk/ HTTP/1.1" 500 27
ERROR 2018-09-17 09:26:52,053 exception 135 Internal Server Error: /talk/
Traceback (most recent call last):
  File "/Applications/anaconda3/lib/python3.6/site-packages/django/db/backends/utils.py", line 62, in execute
    return self.cursor.execute(sql)
  File "/Applications/anaconda3/lib/python3.6/site-packages/django/db/backends/sqlite3/base.py", line 326, in execute
    return Database.Cursor.execute(self, query)
sqlite3.OperationalError: near "*": syntax error

The above exception was the direct cause of the following exception:

Traceback (most recent call last):
  File "/Applications/anaconda3/lib/python3.6/site-packages/pandas/io/sql.py", line 1409, in execute
    cur.execute(*args)
  File "/Applications/anaconda3/lib/python3.6/site-packages/django/db/backends/utils.py", line 64, in execute
    return self.cursor.execute(sql, params)
  File "/Applications/anaconda3/lib/python3.6/site-packages/django/db/utils.py", line 94, in __exit__
    six.reraise(dj_exc_type, dj_exc_value, traceback)
  File "/Applications/anaconda3/lib/python3.6/site-packages/django/utils/six.py", line 685, in reraise
    raise value.with_traceback(tb)
  File "/Applications/anaconda3/lib/python3.6/site-packages/django/db/backends/utils.py", line 62, in execute
    return self.cursor.execute(sql)
  File "/Applications/anaconda3/lib/python3.6/site-packages/django/db/backends/sqlite3/base.py", line 326, in execute
    return Database.Cursor.execute(self, query)
django.db.utils.OperationalError: near "*": syntax error

During handling of the above exception, another exception occurred:

Traceback (most recent call last):
  File "/Applications/anaconda3/lib/python3.6/site-packages/django/core/handlers/exception.py", line 41, in inner
    response = get_response(request)
  File "/Applications/anaconda3/lib/python3.6/site-packages/django/core/handlers/base.py", line 187, in _get_response
    response = self.process_exception_by_middleware(e, request)
  File "/Applications/anaconda3/lib/python3.6/site-packages/django/core/handlers/base.py", line 185, in _get_response
    response = wrapped_callback(request, *callback_args, **callback_kwargs)
  File "/Applications/anaconda3/lib/python3.6/site-packages/django/views/decorators/csrf.py", line 58, in wrapped_view
    return view_func(*args, **kwargs)
  File "/Applications/anaconda3/lib/python3.6/site-packages/django/views/generic/base.py", line 68, in view
    return self.dispatch(request, *args, **kwargs)
  File "/Applications/anaconda3/lib/python3.6/site-packages/django/views/generic/base.py", line 88, in dispatch
    return handler(request, *args, **kwargs)
  File "/Users/mq/Desktop/work_Pro/Code/Project/WeChat/Tax_consult/wechat/views.py", line 213, in post
    list_count, list_dic = self.talk_query(source)
  File "/Users/mq/Desktop/work_Pro/Code/Project/WeChat/Tax_consult/wechat/views.py", line 238, in talk_query
    df = pd.read_sql_query(sql, connection)
  File "/Applications/anaconda3/lib/python3.6/site-packages/pandas/io/sql.py", line 332, in read_sql_query
    parse_dates=parse_dates, chunksize=chunksize)
  File "/Applications/anaconda3/lib/python3.6/site-packages/pandas/io/sql.py", line 1444, in read_query
    cursor = self.execute(*args)
  File "/Applications/anaconda3/lib/python3.6/site-packages/pandas/io/sql.py", line 1421, in execute
    raise_with_traceback(ex)
  File "/Applications/anaconda3/lib/python3.6/site-packages/pandas/compat/__init__.py", line 385, in raise_with_traceback
    raise exc.with_traceback(traceback)
  File "/Applications/anaconda3/lib/python3.6/site-packages/pandas/io/sql.py", line 1409, in execute
    cur.execute(*args)
  File "/Applications/anaconda3/lib/python3.6/site-packages/django/db/backends/utils.py", line 64, in execute
    return self.cursor.execute(sql, params)
  File "/Applications/anaconda3/lib/python3.6/site-packages/django/db/utils.py", line 94, in __exit__
    six.reraise(dj_exc_type, dj_exc_value, traceback)
  File "/Applications/anaconda3/lib/python3.6/site-packages/django/utils/six.py", line 685, in reraise
    raise value.with_traceback(tb)
  File "/Applications/anaconda3/lib/python3.6/site-packages/django/db/backends/utils.py", line 62, in execute
    return self.cursor.execute(sql)
  File "/Applications/anaconda3/lib/python3.6/site-packages/django/db/backends/sqlite3/base.py", line 326, in execute
    return Database.Cursor.execute(self, query)
pandas.io.sql.DatabaseError: Execution failed on sql 'select distinct(*) from 'asks_answer' where class4 LIKE '%启用的新版增值税发票都有哪些变化？%'': near "*": syntax error
ERROR 2018-09-17 09:26:52,061 basehttp 124 "POST /talk/ HTTP/1.1" 500 27
ERROR 2018-09-17 09:27:07,132 exception 135 Internal Server Error: /talk/
Traceback (most recent call last):
  File "/Applications/anaconda3/lib/python3.6/site-packages/django/db/backends/utils.py", line 62, in execute
    return self.cursor.execute(sql)
  File "/Applications/anaconda3/lib/python3.6/site-packages/django/db/backends/sqlite3/base.py", line 326, in execute
    return Database.Cursor.execute(self, query)
sqlite3.OperationalError: near "*": syntax error

The above exception was the direct cause of the following exception:

Traceback (most recent call last):
  File "/Applications/anaconda3/lib/python3.6/site-packages/pandas/io/sql.py", line 1409, in execute
    cur.execute(*args)
  File "/Applications/anaconda3/lib/python3.6/site-packages/django/db/backends/utils.py", line 64, in execute
    return self.cursor.execute(sql, params)
  File "/Applications/anaconda3/lib/python3.6/site-packages/django/db/utils.py", line 94, in __exit__
    six.reraise(dj_exc_type, dj_exc_value, traceback)
  File "/Applications/anaconda3/lib/python3.6/site-packages/django/utils/six.py", line 685, in reraise
    raise value.with_traceback(tb)
  File "/Applications/anaconda3/lib/python3.6/site-packages/django/db/backends/utils.py", line 62, in execute
    return self.cursor.execute(sql)
  File "/Applications/anaconda3/lib/python3.6/site-packages/django/db/backends/sqlite3/base.py", line 326, in execute
    return Database.Cursor.execute(self, query)
django.db.utils.OperationalError: near "*": syntax error

During handling of the above exception, another exception occurred:

Traceback (most recent call last):
  File "/Applications/anaconda3/lib/python3.6/site-packages/django/core/handlers/exception.py", line 41, in inner
    response = get_response(request)
  File "/Applications/anaconda3/lib/python3.6/site-packages/django/core/handlers/base.py", line 187, in _get_response
    response = self.process_exception_by_middleware(e, request)
  File "/Applications/anaconda3/lib/python3.6/site-packages/django/core/handlers/base.py", line 185, in _get_response
    response = wrapped_callback(request, *callback_args, **callback_kwargs)
  File "/Applications/anaconda3/lib/python3.6/site-packages/django/views/decorators/csrf.py", line 58, in wrapped_view
    return view_func(*args, **kwargs)
  File "/Applications/anaconda3/lib/python3.6/site-packages/django/views/generic/base.py", line 68, in view
    return self.dispatch(request, *args, **kwargs)
  File "/Applications/anaconda3/lib/python3.6/site-packages/django/views/generic/base.py", line 88, in dispatch
    return handler(request, *args, **kwargs)
  File "/Users/mq/Desktop/work_Pro/Code/Project/WeChat/Tax_consult/wechat/views.py", line 213, in post
    list_count, list_dic = self.talk_query(source)
  File "/Users/mq/Desktop/work_Pro/Code/Project/WeChat/Tax_consult/wechat/views.py", line 238, in talk_query
    df = pd.read_sql_query(sql, connection)
  File "/Applications/anaconda3/lib/python3.6/site-packages/pandas/io/sql.py", line 332, in read_sql_query
    parse_dates=parse_dates, chunksize=chunksize)
  File "/Applications/anaconda3/lib/python3.6/site-packages/pandas/io/sql.py", line 1444, in read_query
    cursor = self.execute(*args)
  File "/Applications/anaconda3/lib/python3.6/site-packages/pandas/io/sql.py", line 1421, in execute
    raise_with_traceback(ex)
  File "/Applications/anaconda3/lib/python3.6/site-packages/pandas/compat/__init__.py", line 385, in raise_with_traceback
    raise exc.with_traceback(traceback)
  File "/Applications/anaconda3/lib/python3.6/site-packages/pandas/io/sql.py", line 1409, in execute
    cur.execute(*args)
  File "/Applications/anaconda3/lib/python3.6/site-packages/django/db/backends/utils.py", line 64, in execute
    return self.cursor.execute(sql, params)
  File "/Applications/anaconda3/lib/python3.6/site-packages/django/db/utils.py", line 94, in __exit__
    six.reraise(dj_exc_type, dj_exc_value, traceback)
  File "/Applications/anaconda3/lib/python3.6/site-packages/django/utils/six.py", line 685, in reraise
    raise value.with_traceback(tb)
  File "/Applications/anaconda3/lib/python3.6/site-packages/django/db/backends/utils.py", line 62, in execute
    return self.cursor.execute(sql)
  File "/Applications/anaconda3/lib/python3.6/site-packages/django/db/backends/sqlite3/base.py", line 326, in execute
    return Database.Cursor.execute(self, query)
pandas.io.sql.DatabaseError: Execution failed on sql 'select distinct(*) from 'asks_answer' where class4 LIKE '%启用的新版增值税发票都有哪些变化？%'': near "*": syntax error
ERROR 2018-09-17 09:27:07,139 basehttp 124 "POST /talk/ HTTP/1.1" 500 27
ERROR 2018-09-17 09:27:26,738 exception 135 Internal Server Error: /talk/
Traceback (most recent call last):
  File "/Applications/anaconda3/lib/python3.6/site-packages/django/db/backends/utils.py", line 62, in execute
    return self.cursor.execute(sql)
  File "/Applications/anaconda3/lib/python3.6/site-packages/django/db/backends/sqlite3/base.py", line 326, in execute
    return Database.Cursor.execute(self, query)
sqlite3.OperationalError: near "*": syntax error

The above exception was the direct cause of the following exception:

Traceback (most recent call last):
  File "/Applications/anaconda3/lib/python3.6/site-packages/pandas/io/sql.py", line 1409, in execute
    cur.execute(*args)
  File "/Applications/anaconda3/lib/python3.6/site-packages/django/db/backends/utils.py", line 64, in execute
    return self.cursor.execute(sql, params)
  File "/Applications/anaconda3/lib/python3.6/site-packages/django/db/utils.py", line 94, in __exit__
    six.reraise(dj_exc_type, dj_exc_value, traceback)
  File "/Applications/anaconda3/lib/python3.6/site-packages/django/utils/six.py", line 685, in reraise
    raise value.with_traceback(tb)
  File "/Applications/anaconda3/lib/python3.6/site-packages/django/db/backends/utils.py", line 62, in execute
    return self.cursor.execute(sql)
  File "/Applications/anaconda3/lib/python3.6/site-packages/django/db/backends/sqlite3/base.py", line 326, in execute
    return Database.Cursor.execute(self, query)
django.db.utils.OperationalError: near "*": syntax error

During handling of the above exception, another exception occurred:

Traceback (most recent call last):
  File "/Applications/anaconda3/lib/python3.6/site-packages/django/core/handlers/exception.py", line 41, in inner
    response = get_response(request)
  File "/Applications/anaconda3/lib/python3.6/site-packages/django/core/handlers/base.py", line 187, in _get_response
    response = self.process_exception_by_middleware(e, request)
  File "/Applications/anaconda3/lib/python3.6/site-packages/django/core/handlers/base.py", line 185, in _get_response
    response = wrapped_callback(request, *callback_args, **callback_kwargs)
  File "/Applications/anaconda3/lib/python3.6/site-packages/django/views/decorators/csrf.py", line 58, in wrapped_view
    return view_func(*args, **kwargs)
  File "/Applications/anaconda3/lib/python3.6/site-packages/django/views/generic/base.py", line 68, in view
    return self.dispatch(request, *args, **kwargs)
  File "/Applications/anaconda3/lib/python3.6/site-packages/django/views/generic/base.py", line 88, in dispatch
    return handler(request, *args, **kwargs)
  File "/Users/mq/Desktop/work_Pro/Code/Project/WeChat/Tax_consult/wechat/views.py", line 213, in post
    list_count, list_dic = self.talk_query(source)
  File "/Users/mq/Desktop/work_Pro/Code/Project/WeChat/Tax_consult/wechat/views.py", line 238, in talk_query
    df = pd.read_sql_query(sql, connection)
  File "/Applications/anaconda3/lib/python3.6/site-packages/pandas/io/sql.py", line 332, in read_sql_query
    parse_dates=parse_dates, chunksize=chunksize)
  File "/Applications/anaconda3/lib/python3.6/site-packages/pandas/io/sql.py", line 1444, in read_query
    cursor = self.execute(*args)
  File "/Applications/anaconda3/lib/python3.6/site-packages/pandas/io/sql.py", line 1421, in execute
    raise_with_traceback(ex)
  File "/Applications/anaconda3/lib/python3.6/site-packages/pandas/compat/__init__.py", line 385, in raise_with_traceback
    raise exc.with_traceback(traceback)
  File "/Applications/anaconda3/lib/python3.6/site-packages/pandas/io/sql.py", line 1409, in execute
    cur.execute(*args)
  File "/Applications/anaconda3/lib/python3.6/site-packages/django/db/backends/utils.py", line 64, in execute
    return self.cursor.execute(sql, params)
  File "/Applications/anaconda3/lib/python3.6/site-packages/django/db/utils.py", line 94, in __exit__
    six.reraise(dj_exc_type, dj_exc_value, traceback)
  File "/Applications/anaconda3/lib/python3.6/site-packages/django/utils/six.py", line 685, in reraise
    raise value.with_traceback(tb)
  File "/Applications/anaconda3/lib/python3.6/site-packages/django/db/backends/utils.py", line 62, in execute
    return self.cursor.execute(sql)
  File "/Applications/anaconda3/lib/python3.6/site-packages/django/db/backends/sqlite3/base.py", line 326, in execute
    return Database.Cursor.execute(self, query)
pandas.io.sql.DatabaseError: Execution failed on sql 'select distinct(*) from 'asks_answer' where class4 LIKE '%增值税%'': near "*": syntax error
ERROR 2018-09-17 09:27:26,745 basehttp 124 "POST /talk/ HTTP/1.1" 500 27
ERROR 2018-09-17 09:30:29,704 exception 135 Internal Server Error: /talk/
Traceback (most recent call last):
  File "/Applications/anaconda3/lib/python3.6/site-packages/django/core/handlers/exception.py", line 41, in inner
    response = get_response(request)
  File "/Applications/anaconda3/lib/python3.6/site-packages/django/core/handlers/base.py", line 187, in _get_response
    response = self.process_exception_by_middleware(e, request)
  File "/Applications/anaconda3/lib/python3.6/site-packages/django/core/handlers/base.py", line 185, in _get_response
    response = wrapped_callback(request, *callback_args, **callback_kwargs)
  File "/Applications/anaconda3/lib/python3.6/site-packages/django/views/decorators/csrf.py", line 58, in wrapped_view
    return view_func(*args, **kwargs)
  File "/Applications/anaconda3/lib/python3.6/site-packages/django/views/generic/base.py", line 68, in view
    return self.dispatch(request, *args, **kwargs)
  File "/Applications/anaconda3/lib/python3.6/site-packages/django/views/generic/base.py", line 88, in dispatch
    return handler(request, *args, **kwargs)
  File "/Users/mq/Desktop/work_Pro/Code/Project/WeChat/Tax_consult/wechat/views.py", line 212, in post
    list_count, list_dic = self.talk_query(source)
  File "/Users/mq/Desktop/work_Pro/Code/Project/WeChat/Tax_consult/wechat/views.py", line 238, in talk_query
    df = df.drop_duplicates(df["class4"])
  File "/Applications/anaconda3/lib/python3.6/site-packages/pandas/core/frame.py", line 3535, in drop_duplicates
    duplicated = self.duplicated(subset, keep=keep)
  File "/Applications/anaconda3/lib/python3.6/site-packages/pandas/core/frame.py", line 3582, in duplicated
    labels, shape = map(list, zip(*map(f, vals)))
ValueError: not enough values to unpack (expected 2, got 0)
ERROR 2018-09-17 09:30:29,713 basehttp 124 "POST /talk/ HTTP/1.1" 500 27
ERROR 2018-09-17 09:30:49,246 exception 135 Internal Server Error: /talk/
Traceback (most recent call last):
  File "/Applications/anaconda3/lib/python3.6/site-packages/django/core/handlers/exception.py", line 41, in inner
    response = get_response(request)
  File "/Applications/anaconda3/lib/python3.6/site-packages/django/core/handlers/base.py", line 187, in _get_response
    response = self.process_exception_by_middleware(e, request)
  File "/Applications/anaconda3/lib/python3.6/site-packages/django/core/handlers/base.py", line 185, in _get_response
    response = wrapped_callback(request, *callback_args, **callback_kwargs)
  File "/Applications/anaconda3/lib/python3.6/site-packages/django/views/decorators/csrf.py", line 58, in wrapped_view
    return view_func(*args, **kwargs)
  File "/Applications/anaconda3/lib/python3.6/site-packages/django/views/generic/base.py", line 68, in view
    return self.dispatch(request, *args, **kwargs)
  File "/Applications/anaconda3/lib/python3.6/site-packages/django/views/generic/base.py", line 88, in dispatch
    return handler(request, *args, **kwargs)
  File "/Users/mq/Desktop/work_Pro/Code/Project/WeChat/Tax_consult/wechat/views.py", line 212, in post
    list_count, list_dic = self.talk_query(source)
  File "/Users/mq/Desktop/work_Pro/Code/Project/WeChat/Tax_consult/wechat/views.py", line 238, in talk_query
    df = df.drop_duplicates(df["class4"])
  File "/Applications/anaconda3/lib/python3.6/site-packages/pandas/core/frame.py", line 3535, in drop_duplicates
    duplicated = self.duplicated(subset, keep=keep)
  File "/Applications/anaconda3/lib/python3.6/site-packages/pandas/core/frame.py", line 3582, in duplicated
    labels, shape = map(list, zip(*map(f, vals)))
ValueError: not enough values to unpack (expected 2, got 0)
ERROR 2018-09-17 09:30:49,254 basehttp 124 "POST /talk/ HTTP/1.1" 500 27
ERROR 2018-09-17 09:31:35,824 exception 135 Internal Server Error: /talk/
Traceback (most recent call last):
  File "/Applications/anaconda3/lib/python3.6/site-packages/django/core/handlers/exception.py", line 41, in inner
    response = get_response(request)
  File "/Applications/anaconda3/lib/python3.6/site-packages/django/core/handlers/base.py", line 187, in _get_response
    response = self.process_exception_by_middleware(e, request)
  File "/Applications/anaconda3/lib/python3.6/site-packages/django/core/handlers/base.py", line 185, in _get_response
    response = wrapped_callback(request, *callback_args, **callback_kwargs)
  File "/Applications/anaconda3/lib/python3.6/site-packages/django/views/decorators/csrf.py", line 58, in wrapped_view
    return view_func(*args, **kwargs)
  File "/Applications/anaconda3/lib/python3.6/site-packages/django/views/generic/base.py", line 68, in view
    return self.dispatch(request, *args, **kwargs)
  File "/Applications/anaconda3/lib/python3.6/site-packages/django/views/generic/base.py", line 88, in dispatch
    return handler(request, *args, **kwargs)
  File "/Users/mq/Desktop/work_Pro/Code/Project/WeChat/Tax_consult/wechat/views.py", line 212, in post
    list_count, list_dic = self.talk_query(source)
  File "/Users/mq/Desktop/work_Pro/Code/Project/WeChat/Tax_consult/wechat/views.py", line 238, in talk_query
    df = df.drop_duplicates(df["class4"])
  File "/Applications/anaconda3/lib/python3.6/site-packages/pandas/core/frame.py", line 3535, in drop_duplicates
    duplicated = self.duplicated(subset, keep=keep)
  File "/Applications/anaconda3/lib/python3.6/site-packages/pandas/core/frame.py", line 3582, in duplicated
    labels, shape = map(list, zip(*map(f, vals)))
ValueError: not enough values to unpack (expected 2, got 0)
ERROR 2018-09-17 09:31:35,904 basehttp 124 "POST /talk/ HTTP/1.1" 500 27
ERROR 2018-09-17 09:43:17,718 exception 135 Internal Server Error: /talk/
Traceback (most recent call last):
  File "/Applications/anaconda3/lib/python3.6/site-packages/django/core/handlers/exception.py", line 41, in inner
    response = get_response(request)
  File "/Applications/anaconda3/lib/python3.6/site-packages/django/core/handlers/base.py", line 187, in _get_response
    response = self.process_exception_by_middleware(e, request)
  File "/Applications/anaconda3/lib/python3.6/site-packages/django/core/handlers/base.py", line 185, in _get_response
    response = wrapped_callback(request, *callback_args, **callback_kwargs)
  File "/Applications/anaconda3/lib/python3.6/site-packages/django/views/decorators/csrf.py", line 58, in wrapped_view
    return view_func(*args, **kwargs)
  File "/Applications/anaconda3/lib/python3.6/site-packages/django/views/generic/base.py", line 68, in view
    return self.dispatch(request, *args, **kwargs)
  File "/Applications/anaconda3/lib/python3.6/site-packages/django/views/generic/base.py", line 88, in dispatch
    return handler(request, *args, **kwargs)
  File "/Users/mq/Desktop/work_Pro/Code/Project/WeChat/Tax_consult/wechat/views.py", line 218, in post
    list_res[head]
TypeError: list indices must be integers or slices, not str
ERROR 2018-09-17 09:43:17,736 basehttp 124 "POST /talk/ HTTP/1.1" 500 27
